<?xml version="1.0" encoding="utf-8"?>
<!-- This URDF was automatically created by SolidWorks to URDF Exporter! Originally created by Stephen Brawner (brawner@gmail.com)
     Commit Version: 1.6.0-4-g7f85cfe  Build Version: 1.6.7995.38578
     For more information, please see http://wiki.ros.org/sw_urdf_exporter -->
<robot
  xmlns:xacro="http://www.ros.org/wiki/xacro"
  name="Articulated_Arm_Rev2">
  <link
    name="chassis_base">
    <inertial>
      <origin
        xyz="2.3216E-06 0.15427 -0.14441"
        rpy="0 0 0" />
      <mass
        value="3.9263" />
      <inertia
        ixx="0.06005"
        ixy="-1.0387E-05"
        ixz="-2.8316E-06"
        iyy="0.066857"
        iyz="-1.6117E-05"
        izz="0.11686" />
    </inertial>
    <visual>
      <origin
        xyz="0 0 0"
        rpy="0 0 0" />
      <geometry>
        <mesh
          filename="package://arm_ik/meshes/chassis_base.STL" />
      </geometry>
      <material
        name="">
        <color
          rgba="0.75294 0.75294 0.75294 1" />
      </material>
    </visual>
    <collision>
      <origin
        xyz="0 0 0"
        rpy="0 0 0" />
      <geometry>
        <mesh
          filename="package://arm_ik/meshes/chassis_base.STL" />
      </geometry>
    </collision>
  </link>
  <link
    name="shoulder">
    <inertial>
      <origin
        xyz="-0.002786 0.0016983 -0.010262"
        rpy="0 0 0" />
      <mass
        value="4.0459" />
      <inertia
        ixx="0.0032096"
        ixy="8.5082E-07"
        ixz="1.6802E-06"
        iyy="0.0021677"
        iyz="-2.1022E-06"
        izz="0.0022043" />
    </inertial>
    <visual>
      <origin
        xyz="0 0 0"
        rpy="0 0 0" />
      <geometry>
        <mesh
          filename="package://arm_ik/meshes/shoulder.STL" />
      </geometry>
      <material
        name="">
        <color
          rgba="0.75294 0.75294 0.75294 1" />
      </material>
    </visual>
    <collision>
      <origin
        xyz="0 0 0"
        rpy="0 0 0" />
      <geometry>
        <mesh
          filename="package://arm_ik/meshes/shoulder.STL" />
      </geometry>
    </collision>
  </link>
  <joint
    name="ax1-turret"
    type="revolute">
    <origin
      xyz="0 0 0"
      rpy="0 0 0" />
    <parent
      link="chassis_base" />
    <child
      link="shoulder" />
    <axis
      xyz="0 0 1" />  <!-- Changed from 0 0 -1 to accomodate modelling assumptions-->
    <limit
      lower="-6.28"
      upper="6.28"
      effort="0"
      velocity="0" />
  </joint>
  <link
    name="upper_arm">
    <inertial>
      <origin
        xyz="0.061519 0.0010853 0.25523"
        rpy="0 0 0" />
      <mass
        value="1.6029" />
      <inertia
        ixx="0.024959"
        ixy="-9.239E-07"
        ixz="-7.8409E-08"
        iyy="0.023597"
        iyz="-2.1824E-05"
        izz="0.0014813" />
    </inertial>
    <visual>
      <origin
        xyz="0 0 0"
        rpy="0 0 0" />
      <geometry>
        <mesh
          filename="package://arm_ik/meshes/upper_arm.STL" />
      </geometry>
      <material
        name="">
        <color
          rgba="0.75294 0.75294 0.75294 1" />
      </material>
    </visual>
    <collision>
      <origin
        xyz="0 0 0"
        rpy="0 0 0" />
      <geometry>
        <mesh
          filename="package://arm_ik/meshes/upper_arm.STL" />
      </geometry>
    </collision>
  </link>
  <joint
    name="ax2-shoulder"
    type="revolute">
    <origin
      xyz="0 0 0"
      rpy="0 0 0" />
    <parent
      link="shoulder" />
    <child
      link="upper_arm" />
    <axis
      xyz="1 0 0" /> <!-- changed from -1 0 0 to accomodate modelling assumption-->
    <limit
      lower="-6.28"
      upper="6.28"
      effort="0"
      velocity="0" />
  </joint>
  <link
    name="elbow">
    <inertial>
      <origin
        xyz="0.022147 0.0071039 0.0016285"
        rpy="0 0 0" />
      <mass
        value="1.2215" />
      <inertia
        ixx="0.00064071"
        ixy="-6.2505E-09"
        ixz="2.0116E-07"
        iyy="0.00054905"
        iyz="-1.2587E-07"
        izz="0.00057172" />
    </inertial>
    <visual>
      <origin
        xyz="0 -0.5 0"
        rpy="0 0 0" />
      <geometry>
        <mesh
          filename="package://arm_ik/meshes/elbow.STL" />
      </geometry>
      <material
        name="">
        <color
          rgba="0.75294 0.75294 0.75294 1" />
      </material>
    </visual>
    <collision>
      <origin
        xyz="0 -0.5 0"
        rpy="0 0 0" />
      <geometry>
        <mesh
          filename="package://arm_ik/meshes/elbow.STL" />
      </geometry>
    </collision>
  </link>
  <joint
    name="ax3-elbow"
    type="revolute">
    <origin
      xyz="0 0 0.5"
      rpy="1.5707963267949 0 0" />
    <parent
      link="upper_arm" />
    <child
      link="elbow" />
    <axis
      xyz="1 0 0" />
    <limit
      lower="-6.28"
      upper="6.28"
      effort="0"
      velocity="0" />
  </joint>
  <link
    name="forearm">
    <inertial>
      <origin
        xyz="-8.8386E-06 0.31164 5.6825E-10"
        rpy="0 0 0" />
      <mass
        value="0.89118" />
      <inertia
        ixx="0.0033301"
        ixy="-1.1312E-08"
        ixz="-1.2962E-10"
        iyy="0.00027094"
        iyz="-2.7225E-12"
        izz="0.0032672" />
    </inertial>
    <visual>
      <origin
        xyz="0 -0.5 0"
        rpy="0 0 0" />
      <geometry>
        <mesh
          filename="package://arm_ik/meshes/forearm.STL" />
      </geometry>
      <material
        name="">
        <color
          rgba="0.75294 0.75294 0.75294 1" />
      </material>
    </visual>
    <collision>
      <origin
        xyz="0 -0.5 0"
        rpy="0 0 0" />
      <geometry>
        <mesh
          filename="package://arm_ik/meshes/forearm.STL" />
      </geometry>
    </collision>
  </link>
  <joint
    name="ax4-elbow-roll"
    type="revolute">
    <origin
      xyz="0 0 0"
      rpy="0 0 0" />
    <parent
      link="elbow" />
    <child
      link="forearm" />
    <axis
      xyz="0 -1 0" />
    <limit
      lower="-6.28"
      upper="6.28"
      effort="0"
      velocity="0" />
  </joint>
  <link
    name="wrist_bend">
    <inertial>
      <origin
        xyz="7.1966E-09 -0.0075191 0.0040143"
        rpy="0 0 0" />
      <mass
        value="0.51608" />
      <inertia
        ixx="0.00015539"
        ixy="2.2832E-11"
        ixz="1.2318E-10"
        iyy="0.0001068"
        iyz="1.1644E-06"
        izz="0.00010575" />
    </inertial>
    <visual>
      <origin
        xyz="0 -1 0"
        rpy="0 0 0" />
      <geometry>
        <mesh
          filename="package://arm_ik/meshes/wrist_bend.STL" />
      </geometry>
      <material
        name="">
        <color
          rgba="0.75294 0.75294 0.75294 1" />
      </material>
    </visual>
    <collision>
      <origin
        xyz="0 -1 0"
        rpy="0 0 0" />
      <geometry>
        <mesh
          filename="package://arm_ik/meshes/wrist_bend.STL" />
      </geometry>
    </collision>
  </link>
  <joint
    name="ax5-wrist-pitch"
    type="revolute">
    <origin
      xyz="0 0.5 0"
      rpy="0 0 0" />
    <parent
      link="forearm" />
    <child
      link="wrist_bend" />
    <axis
      xyz="-1 0 0" />
    <limit
      lower="-6.28"
      upper="6.28"
      effort="0"
      velocity="0" />
  </joint>
  <link
    name="wrist_roll">
    <inertial>
      <origin
        xyz="1.6506E-07 0.08014 -7.2873E-06"
        rpy="0 0 0" />
      <mass
        value="0.42978" />
      <inertia
        ixx="0.00030077"
        ixy="-3.4923E-11"
        ixz="7.87E-07"
        iyy="0.00016743"
        iyz="-3.1381E-11"
        izz="0.00029688" />
    </inertial>
    <visual>
      <origin
        xyz="0 -1 0"
        rpy="0 ${pi/2} 0" />
      <geometry>
        <mesh
          filename="package://arm_ik/meshes/wrist_roll.STL" />
      </geometry>
      <material
        name="">
        <color
          rgba="0.75294 0.75294 0.75294 1" />
      </material>
    </visual>
    <collision>
      <origin
        xyz="0 -1 0"
        rpy="0 0 0" />
      <geometry>
        <mesh
          filename="package://arm_ik/meshes/wrist_roll.STL" />
      </geometry>
    </collision>
  </link>
  <joint
    name="ax6-wrist-roll"
    type="revolute">
    <origin
      xyz="0 0 0"
      rpy="0 0 0" />
    <parent
      link="wrist_bend" />
    <child
      link="wrist_roll" />
    <axis
      xyz="0 -1 0" />
    <limit
      lower="-6.28"
      upper="6.28"
      effort="0"
      velocity="0" />
  </joint>


  <!-- Defining base frame (fixed to chassis_base) and end-effector frame (fixed to wrist_roll, on the tip) -->
  <!-- These are defined to be more intuitive: x points forward, y points sideway, and z upward.-->
  <xacro:property name="ee_offset" value="0.15" /> <!-- Tip distance from wrist_roll frame-->
  <link name="base_frame"/>
  <link name="ee_frame"/>
  <joint name="base_frame_joint" type="fixed">
    <origin xyz="0 0 0" rpy="0 0 ${3*pi/2}"/>
    <parent link="chassis_base" />
    <child link="base_frame" />
  </joint>
  <joint name="ee_frame_joint" type="fixed">
    <origin xyz="0 ${ee_offset} 0" rpy="${pi} 0 ${pi/2}"/>
    <parent link="wrist_roll"/>
    <child link="ee_frame"/>
  </joint>

</robot>
